<?xml version="1.0"?>
<robot xmlns:xacro="http://www.ros.org/wiki/xacro" name="mower">

  <!-- Include materials -->
  <material name="blue">
    <color rgba="0.0 0.0 0.8 1.0"/>
  </material>
  
  <material name="red">
    <color rgba="0.8 0.0 0.0 1.0"/>
  </material>
  
  <material name="green">
    <color rgba="0.0 0.8 0.0 1.0"/>
  </material>
  
  <material name="grey">
    <color rgba="0.5 0.5 0.5 1.0"/>
  </material>
  
  <material name="black">
    <color rgba="0.0 0.0 0.0 1.0"/>
  </material>

  <!-- Base link - central reference frame -->
  <link name="base_link">
    <!-- This is just a reference frame, no visual or collision geometry -->
  </link>

  <!-- Chassis link - main body of the robot -->
  <link name="chassis">
    <visual>
      <geometry>
        <!-- Chassis dimensions: L:19cm, W:44cm, H:22cm -->
        <box size="0.19 0.44 0.22"/>
      </geometry>
      <material name="blue"/>
    </visual>
    
    <collision>
      <geometry>
        <box size="0.19 0.44 0.22"/>
      </geometry>
    </collision>
  </link>

  <!-- Joint connecting chassis to base_link -->
  <joint name="chassis_joint" type="fixed">
    <parent link="base_link"/>
    <child link="chassis"/>
    <!-- Position chassis so its bottom is at wheel center height (9.75cm) 
         Chassis height is 22cm, so center should be at 9.75 + 11 = 20.75cm -->
    <origin xyz="0.0 0.0 0.2075" rpy="0 0 0"/>
  </joint>

  <!-- Left Drive Wheel -->
  <link name="left_wheel">
    <visual>
      <geometry>
        <!-- Wheel dimensions: Ø19.5cm, W:3.6cm -->
        <cylinder radius="0.0975" length="0.036"/>
      </geometry>
      <material name="black"/>
    </visual>
    
    <collision>
      <geometry>
        <cylinder radius="0.0975" length="0.036"/>
      </geometry>
    </collision>
  </link>

  <!-- Left wheel joint -->
  <joint name="left_wheel_joint" type="continuous">
    <parent link="base_link"/>
    <child link="left_wheel"/>
    <!-- Position: At (0, 23cm, 9.75cm) -->
    <origin xyz="0.0 0.23 0.0975" rpy="-1.5707963 0 0"/>
    <axis xyz="0 0 1"/>
  </joint>

  <!-- Right Drive Wheel -->
  <link name="right_wheel">
    <visual>
      <geometry>
        <!-- Wheel dimensions: Ø19.5cm, W:3.6cm -->
        <cylinder radius="0.0975" length="0.036"/>
      </geometry>
      <material name="black"/>
    </visual>
    
    <collision>
      <geometry>
        <cylinder radius="0.0975" length="0.036"/>
      </geometry>
    </collision>
  </link>

  <!-- Right wheel joint -->
  <joint name="right_wheel_joint" type="continuous">
    <parent link="base_link"/>
    <child link="right_wheel"/>
    <!-- Position: At (0, -23cm, 9.75cm) -->
    <origin xyz="0.0 -0.23 0.0975" rpy="1.5707963 0 0"/>
    <axis xyz="0 0 1"/>
  </joint>

  <!-- Counterweight -->
  <link name="counterweight">
    <visual>
      <geometry>
        <!-- Counterweight dimensions: L:21cm, W:13cm, H:13cm -->
        <box size="0.21 0.13 0.13"/>
      </geometry>
      <material name="grey"/>
    </visual>
    
    <collision>
      <geometry>
        <box size="0.21 0.13 0.13"/>
      </geometry>
    </collision>
  </link>

  <!-- Counterweight joint - fixed to chassis -->
  <joint name="counterweight_joint" type="fixed">
    <parent link="chassis"/>
    <child link="counterweight"/>
    <!-- Position at rear of chassis, butting up against it
         Chassis length is 19cm, so half is 9.5cm
         Counterweight length is 21cm, so half is 10.5cm
         Total distance from chassis center to counterweight center: 9.5/2 + 10.5 = 20cm
         
         Counterweight bottom should align with chassis bottom:
         Chassis center at 20.75cm, counterweight height 13cm
         Counterweight center should be at 9.75 + 6.5 = 16.25cm
         Relative to chassis: 16.25 - 20.75 = -4.5cm -->
    <origin xyz="-0.20 0.0 -0.045" rpy="0 0 0"/>
  </joint>

  <!-- Front Roller -->
  <link name="front_roller">
    <visual>
      <geometry>
        <!-- Front roller dimensions: Ø8.89cm, W:33cm -->
        <cylinder radius="0.04445" length="0.33"/>
      </geometry>
      <material name="green"/>
    </visual>
    
    <collision>
      <geometry>
        <cylinder radius="0.04445" length="0.33"/>
      </geometry>
    </collision>
  </link>

  <!-- Front roller joint -->
  <joint name="front_roller_joint" type="continuous">
    <parent link="base_link"/>
    <child link="front_roller"/>
    <!-- Position: At (48cm, 0, 4.445cm) -->
    <origin xyz="0.48 0.0 0.04445" rpy="-1.5707963 0 0"/>
    <axis xyz="0 0 1"/>
  </joint>

  <!-- Cutting Reel -->
  <link name="reel">
    <visual>
      <geometry>
        <!-- Reel dimensions: Ø17.5cm, W:47cm -->
        <cylinder radius="0.0875" length="0.47"/>
      </geometry>
      <material name="red"/>
    </visual>
    
    <collision>
      <geometry>
        <cylinder radius="0.0875" length="0.47"/>
      </geometry>
    </collision>
  </link>

  <!-- Reel joint -->
  <joint name="reel_joint" type="continuous">
    <parent link="base_link"/>
    <child link="reel"/>
    <!-- Position: Raise reel 3cm off ground
         Reel radius is 8.75cm, so center should be at 3 + 8.75 = 11.75cm -->
    <origin xyz="0.30 0.0 0.1175" rpy="-1.5707963 0 0"/>
    <axis xyz="0 0 1"/>
  </joint>

  <!-- Reel Motor -->
  <link name="reel_motor">
    <visual>
      <geometry>
        <!-- Motor dimensions: cylinder with 2cm radius, 12cm height -->
        <cylinder radius="0.02" length="0.12"/>
      </geometry>
      <material name="black"/>
    </visual>
    
    <collision>
      <geometry>
        <cylinder radius="0.02" length="0.12"/>
      </geometry>
    </collision>
  </link>

  <!-- Reel motor joint - fixed to chassis -->
  <joint name="reel_motor_joint" type="fixed">
    <parent link="chassis"/>
    <child link="reel_motor"/>
    <!-- Position: At (21.8cm, -23.5cm, 17.55cm) relative to base_link
         Since chassis is now at Z=20.75cm, adjust relative position:
         Z_relative = 17.55 - 20.75 = -3.2cm -->
    <origin xyz="0.218 -0.235 -0.032" rpy="-1.5707963 0 0"/>
  </joint>

</robot>
