<?xml version="1.0"?>
<robot xmlns:xacro="http://www.ros.org/wiki/xacro" name="mower">

  <!-- Include materials -->
  <material name="blue">
    <color rgba="0.0 0.0 0.8 1.0"/>
  </material>
  
  <material name="red">
    <color rgba="0.8 0.0 0.0 1.0"/>
  </material>
  
  <material name="green">
    <color rgba="0.0 0.8 0.0 1.0"/>
  </material>
  
  <material name="grey">
    <color rgba="0.5 0.5 0.5 1.0"/>
  </material>
  
  <material name="black">
    <color rgba="0.0 0.0 0.0 1.0"/>
  </material>

  <!-- Base link - central reference frame -->
  <link name="base_link">
    <!-- This is just a reference frame, no visual or collision geometry -->
  </link>

  <!-- Chassis link - main body of the robot -->
  <link name="chassis">
    <visual>
      <geometry>
        <!-- Chassis dimensions: L:19cm, W:44cm, H:22cm -->
        <box size="0.19 0.44 0.22"/>
      </geometry>
      <material name="blue"/>
    </visual>
    
    <collision>
      <geometry>
        <box size="0.19 0.44 0.22"/>
      </geometry>
    </collision>
  </link>

  <!-- Joint connecting chassis to base_link -->
  <joint name="chassis_joint" type="fixed">
    <parent link="base_link"/>
    <child link="chassis"/>
    <!-- Position chassis at ground level, centered -->
    <origin xyz="0.0 0.0 0.11" rpy="0 0 0"/>
  </joint>

  <!-- Left Drive Wheel -->
  <link name="left_wheel">
    <visual>
      <geometry>
        <!-- Wheel dimensions: Ø19.5cm, W:3.6cm -->
        <cylinder radius="0.0975" length="0.036"/>
      </geometry>
      <material name="black"/>
    </visual>
    
    <collision>
      <geometry>
        <cylinder radius="0.0975" length="0.036"/>
      </geometry>
    </collision>
  </link>

  <!-- Left wheel joint -->
  <joint name="left_wheel_joint" type="continuous">
    <parent link="base_link"/>
    <child link="left_wheel"/>
    <!-- Position: At (0, 23cm, 9.75cm) -->
    <origin xyz="0.0 0.23 0.0975" rpy="-1.5707963 0 0"/>
    <axis xyz="0 0 1"/>
  </joint>

  <!-- Right Drive Wheel -->
  <link name="right_wheel">
    <visual>
      <geometry>
        <!-- Wheel dimensions: Ø19.5cm, W:3.6cm -->
        <cylinder radius="0.0975" length="0.036"/>
      </geometry>
      <material name="black"/>
    </visual>
    
    <collision>
      <geometry>
        <cylinder radius="0.0975" length="0.036"/>
      </geometry>
    </collision>
  </link>

  <!-- Right wheel joint -->
  <joint name="right_wheel_joint" type="continuous">
    <parent link="base_link"/>
    <child link="right_wheel"/>
    <!-- Position: At (0, -23cm, 9.75cm) -->
    <origin xyz="0.0 -0.23 0.0975" rpy="1.5707963 0 0"/>
    <axis xyz="0 0 1"/>
  </joint>

</robot>
